Traceback (most recent call last):
  File "/home/gslee/anaconda3/lib/python3.9/site-packages/jupyter_cache/executors/utils.py", line 51, in single_nb_execution
    executenb(
  File "/home/gslee/anaconda3/lib/python3.9/site-packages/nbclient/client.py", line 1204, in execute
    return NotebookClient(nb=nb, resources=resources, km=km, **kwargs).execute()
  File "/home/gslee/anaconda3/lib/python3.9/site-packages/nbclient/util.py", line 84, in wrapped
    return just_run(coro(*args, **kwargs))
  File "/home/gslee/anaconda3/lib/python3.9/site-packages/nbclient/util.py", line 62, in just_run
    return loop.run_until_complete(coro)
  File "/home/gslee/anaconda3/lib/python3.9/asyncio/base_events.py", line 647, in run_until_complete
    return future.result()
  File "/home/gslee/anaconda3/lib/python3.9/site-packages/nbclient/client.py", line 663, in async_execute
    await self.async_execute_cell(
  File "/home/gslee/anaconda3/lib/python3.9/site-packages/nbclient/client.py", line 965, in async_execute_cell
    await self._check_raise_for_error(cell, cell_index, exec_reply)
  File "/home/gslee/anaconda3/lib/python3.9/site-packages/nbclient/client.py", line 862, in _check_raise_for_error
    raise CellExecutionError.from_cell_and_msg(cell, exec_reply_content)
nbclient.exceptions.CellExecutionError: An error occurred while executing the following cell:
------------------
PREVIOUS_MAX_ROWS = pd.options.display.max_rows # ÏõêÎûò 60Ïù¥ Í∏∞Î≥∏.
pd.set_option("max_rows", 20)
------------------

[0;31m---------------------------------------------------------------------------[0m
[0;31mOptionError[0m                               Traceback (most recent call last)
Input [0;32mIn [3][0m, in [0;36m<cell line: 2>[0;34m()[0m
[1;32m      1[0m PREVIOUS_MAX_ROWS [38;5;241m=[39m pd[38;5;241m.[39moptions[38;5;241m.[39mdisplay[38;5;241m.[39mmax_rows [38;5;66;03m# ÏõêÎûò 60Ïù¥ Í∏∞Î≥∏.[39;00m
[0;32m----> 2[0m [43mpd[49m[38;5;241;43m.[39;49m[43mset_option[49m[43m([49m[38;5;124;43m"[39;49m[38;5;124;43mmax_rows[39;49m[38;5;124;43m"[39;49m[43m,[49m[43m [49m[38;5;241;43m20[39;49m[43m)[49m

File [0;32m~/anaconda3/lib/python3.9/site-packages/pandas/_config/config.py:256[0m, in [0;36mCallableDynamicDoc.__call__[0;34m(self, *args, **kwds)[0m
[1;32m    255[0m [38;5;28;01mdef[39;00m [38;5;21m__call__[39m([38;5;28mself[39m, [38;5;241m*[39margs, [38;5;241m*[39m[38;5;241m*[39mkwds):
[0;32m--> 256[0m     [38;5;28;01mreturn[39;00m [38;5;28;43mself[39;49m[38;5;241;43m.[39;49m[38;5;18;43m__func__[39;49m[43m([49m[38;5;241;43m*[39;49m[43margs[49m[43m,[49m[43m [49m[38;5;241;43m*[39;49m[38;5;241;43m*[39;49m[43mkwds[49m[43m)[49m

File [0;32m~/anaconda3/lib/python3.9/site-packages/pandas/_config/config.py:149[0m, in [0;36m_set_option[0;34m(*args, **kwargs)[0m
[1;32m    146[0m     [38;5;28;01mraise[39;00m [38;5;167;01mTypeError[39;00m([38;5;124mf[39m[38;5;124m'[39m[38;5;124m_set_option() got an unexpected keyword argument [39m[38;5;124m"[39m[38;5;132;01m{[39;00mkwarg[38;5;132;01m}[39;00m[38;5;124m"[39m[38;5;124m'[39m)
[1;32m    148[0m [38;5;28;01mfor[39;00m k, v [38;5;129;01min[39;00m [38;5;28mzip[39m(args[::[38;5;241m2[39m], args[[38;5;241m1[39m::[38;5;241m2[39m]):
[0;32m--> 149[0m     key [38;5;241m=[39m [43m_get_single_key[49m[43m([49m[43mk[49m[43m,[49m[43m [49m[43msilent[49m[43m)[49m
[1;32m    151[0m     o [38;5;241m=[39m _get_registered_option(key)
[1;32m    152[0m     [38;5;28;01mif[39;00m o [38;5;129;01mand[39;00m o[38;5;241m.[39mvalidator:

File [0;32m~/anaconda3/lib/python3.9/site-packages/pandas/_config/config.py:116[0m, in [0;36m_get_single_key[0;34m(pat, silent)[0m
[1;32m    114[0m     [38;5;28;01mraise[39;00m OptionError([38;5;124mf[39m[38;5;124m"[39m[38;5;124mNo such keys(s): [39m[38;5;132;01m{[39;00m[38;5;28mrepr[39m(pat)[38;5;132;01m}[39;00m[38;5;124m"[39m)
[1;32m    115[0m [38;5;28;01mif[39;00m [38;5;28mlen[39m(keys) [38;5;241m>[39m [38;5;241m1[39m:
[0;32m--> 116[0m     [38;5;28;01mraise[39;00m OptionError([38;5;124m"[39m[38;5;124mPattern matched multiple keys[39m[38;5;124m"[39m)
[1;32m    117[0m key [38;5;241m=[39m keys[[38;5;241m0[39m]
[1;32m    119[0m [38;5;28;01mif[39;00m [38;5;129;01mnot[39;00m silent:

[0;31mOptionError[0m: 'Pattern matched multiple keys'
OptionError: 'Pattern matched multiple keys'

