Traceback (most recent call last):
  File "/home/gslee/anaconda3/lib/python3.9/site-packages/jupyter_cache/executors/utils.py", line 51, in single_nb_execution
    executenb(
  File "/home/gslee/anaconda3/lib/python3.9/site-packages/nbclient/client.py", line 1112, in execute
    return NotebookClient(nb=nb, resources=resources, km=km, **kwargs).execute()
  File "/home/gslee/anaconda3/lib/python3.9/site-packages/nbclient/util.py", line 74, in wrapped
    return just_run(coro(*args, **kwargs))
  File "/home/gslee/anaconda3/lib/python3.9/site-packages/nbclient/util.py", line 53, in just_run
    return loop.run_until_complete(coro)
  File "/home/gslee/anaconda3/lib/python3.9/asyncio/base_events.py", line 642, in run_until_complete
    return future.result()
  File "/home/gslee/anaconda3/lib/python3.9/site-packages/nbclient/client.py", line 553, in async_execute
    await self.async_execute_cell(
  File "/home/gslee/anaconda3/lib/python3.9/site-packages/nbclient/client.py", line 857, in async_execute_cell
    self._check_raise_for_error(cell, exec_reply)
  File "/home/gslee/anaconda3/lib/python3.9/site-packages/nbclient/client.py", line 760, in _check_raise_for_error
    raise CellExecutionError.from_cell_and_msg(cell, exec_reply_content)
nbclient.exceptions.CellExecutionError: An error occurred while executing the following cell:
------------------
df.groupby(["A", "B"]).value_counts()
------------------

[0;31m---------------------------------------------------------------------------[0m
[0;31mAttributeError[0m                            Traceback (most recent call last)
[0;32m/tmp/ipykernel_301/3252504889.py[0m in [0;36m<module>[0;34m[0m
[0;32m----> 1[0;31m [0mdf[0m[0;34m.[0m[0mgroupby[0m[0;34m([0m[0;34m[[0m[0;34m"A"[0m[0;34m,[0m [0;34m"B"[0m[0;34m][0m[0;34m)[0m[0;34m.[0m[0mvalue_counts[0m[0;34m([0m[0;34m)[0m[0;34m[0m[0;34m[0m[0m
[0m
[0;32m~/anaconda3/lib/python3.9/site-packages/pandas/core/groupby/groupby.py[0m in [0;36m__getattr__[0;34m(self, attr)[0m
[1;32m    909[0m             [0;32mreturn[0m [0mself[0m[0;34m[[0m[0mattr[0m[0;34m][0m[0;34m[0m[0;34m[0m[0m
[1;32m    910[0m [0;34m[0m[0m
[0;32m--> 911[0;31m         raise AttributeError(
[0m[1;32m    912[0m             [0;34mf"'{type(self).__name__}' object has no attribute '{attr}'"[0m[0;34m[0m[0;34m[0m[0m
[1;32m    913[0m         )

[0;31mAttributeError[0m: 'DataFrameGroupBy' object has no attribute 'value_counts'
AttributeError: 'DataFrameGroupBy' object has no attribute 'value_counts'

